djangogirls on ÓÇ† main [‚á°] via üêç v3.10.6 (myvenv)
‚ùØ python manage.py runserver
Watching for file changes with StatReloader
Performing system checks...

Exception in thread django-main-thread:
Traceback (most recent call last):
  File "/Users/Stephen/.pyenv/versions/3.10.6/lib/python3.10/threading.py", line 1016, in _bootstrap_inner
    self.run()
  File "/Users/Stephen/.pyenv/versions/3.10.6/lib/python3.10/threading.py", line 953, in run
    self._target(*self._args, **self._kwargs)
  File "/Users/Stephen/djangogirls/myvenv/lib/python3.10/site-packages/django/utils/autoreload.py", line 64, in wrapper
    fn(*args, **kwargs)
  File "/Users/Stephen/djangogirls/myvenv/lib/python3.10/site-packages/django/core/management/commands/runserver.py", line 118, in inner_run
    self.check(display_num_errors=True)
  File "/Users/Stephen/djangogirls/myvenv/lib/python3.10/site-packages/django/core/management/base.py", line 419, in check
    all_issues = checks.run_checks(
  File "/Users/Stephen/djangogirls/myvenv/lib/python3.10/site-packages/django/core/checks/registry.py", line 76, in run_checks
    new_errors = check(app_configs=app_configs, databases=databases)
  File "/Users/Stephen/djangogirls/myvenv/lib/python3.10/site-packages/django/core/checks/urls.py", line 13, in check_url_config
    return check_resolver(resolver)
  File "/Users/Stephen/djangogirls/myvenv/lib/python3.10/site-packages/django/core/checks/urls.py", line 23, in check_resolver
    return check_method()
  File "/Users/Stephen/djangogirls/myvenv/lib/python3.10/site-packages/django/urls/resolvers.py", line 416, in check
    for pattern in self.url_patterns:
  File "/Users/Stephen/djangogirls/myvenv/lib/python3.10/site-packages/django/utils/functional.py", line 48, in __get__
    res = instance.__dict__[self.name] = self.func(instance)
  File "/Users/Stephen/djangogirls/myvenv/lib/python3.10/site-packages/django/urls/resolvers.py", line 602, in url_patterns
    patterns = getattr(self.urlconf_module, "urlpatterns", self.urlconf_module)
  File "/Users/Stephen/djangogirls/myvenv/lib/python3.10/site-packages/django/utils/functional.py", line 48, in __get__
    res = instance.__dict__[self.name] = self.func(instance)
  File "/Users/Stephen/djangogirls/myvenv/lib/python3.10/site-packages/django/urls/resolvers.py", line 595, in urlconf_module
    return import_module(self.urlconf_name)
  File "/Users/Stephen/.pyenv/versions/3.10.6/lib/python3.10/importlib/__init__.py", line 126, in import_module
    return _bootstrap._gcd_import(name[level:], package, level)
  File "<frozen importlib._bootstrap>", line 1050, in _gcd_import
  File "<frozen importlib._bootstrap>", line 1027, in _find_and_load
  File "<frozen importlib._bootstrap>", line 1006, in _find_and_load_unlocked
  File "<frozen importlib._bootstrap>", line 688, in _load_unlocked
  File "<frozen importlib._bootstrap_external>", line 883, in exec_module
  File "<frozen importlib._bootstrap>", line 241, in _call_with_frames_removed
  File "/Users/Stephen/djangogirls/mysite/urls.py", line 21, in <module>
    path('', include(blog.urls)),
NameError: name 'blog' is not defined